<?xml version="1.0"?>
<!--
  agenticros_amr/model.sdf
  Two-wheel differential-drive AMR with:
    * Chassis link (rectangular)
    * Two driven wheels + one passive caster
    * Forward-facing RGB-D camera (RealSense D435-ish: 640x480 colour + 16-bit depth)
    * 2D GPU lidar (RPLidar-like, 360°, 12 Hz)
    * IMU
    * gz-sim diff-drive + odometry + joint-state systems

  Topic layout (Gazebo side; ros_gz_bridge translates to ROS):
    cmd_vel               → /model/agenticros_amr/cmd_vel
    odom                  → /model/agenticros_amr/odometry
    tf                    → /model/agenticros_amr/tf
    rgb image             → /camera/camera/color/image_raw      (matches real RealSense)
    rgb camera_info       → /camera/camera/color/camera_info
    depth image (16UC1)   → /camera/camera/depth/image_rect_raw
    depth camera_info     → /camera/camera/depth/camera_info
    lidar scan            → /scan
    imu                   → /imu/data
-->
<sdf version="1.9">
  <model name="agenticros_amr">

    <!-- ===================== Chassis ===================== -->
    <link name="base_link">
      <pose>0 0 0.10 0 0 0</pose>
      <inertial>
        <mass>5.0</mass>
        <inertia>
          <ixx>0.10</ixx><iyy>0.15</iyy><izz>0.20</izz>
          <ixy>0</ixy><ixz>0</ixz><iyz>0</iyz>
        </inertia>
      </inertial>
      <collision name="chassis_col">
        <geometry><box><size>0.40 0.30 0.15</size></box></geometry>
      </collision>
      <visual name="chassis_vis">
        <geometry><box><size>0.40 0.30 0.15</size></box></geometry>
        <material><ambient>0.2 0.2 0.25 1</ambient><diffuse>0.3 0.3 0.35 1</diffuse></material>
      </visual>

      <!-- ============ RealSense-D435-like depth camera ============ -->
      <!--
        Mounted at front of the chassis, 0.10 m above the chassis top, looking
        forward (+X). HFOV 87° matches the real D435 depth sensor; FOLLOW_ME
        depth-loop code already assumes this HFOV constant.
      -->
      <sensor name="depth_camera" type="rgbd_camera">
        <pose>0.20 0 0.18 0 0 0</pose>
        <topic>camera</topic>
        <update_rate>30</update_rate>
        <camera>
          <horizontal_fov>1.5184</horizontal_fov>
          <image>
            <width>640</width>
            <height>480</height>
            <format>R8G8B8</format>
          </image>
          <clip>
            <near>0.10</near>
            <far>10.0</far>
          </clip>
          <distortion>
            <k1>0.0</k1><k2>0.0</k2><k3>0.0</k3><p1>0.0</p1><p2>0.0</p2>
          </distortion>
          <optical_frame_id>camera_optical_link</optical_frame_id>
          <depth_camera>
            <output>depths</output>
          </depth_camera>
        </camera>
        <always_on>true</always_on>
        <visualize>false</visualize>
      </sensor>

      <!-- ============ 2D GPU lidar (RPLidar-ish) ============ -->
      <sensor name="gpu_lidar" type="gpu_lidar">
        <pose>0 0 0.20 0 0 0</pose>
        <topic>scan</topic>
        <update_rate>12</update_rate>
        <lidar>
          <scan>
            <horizontal>
              <samples>360</samples>
              <resolution>1</resolution>
              <min_angle>-3.14159</min_angle>
              <max_angle>3.14159</max_angle>
            </horizontal>
          </scan>
          <range>
            <min>0.10</min>
            <max>12.0</max>
            <resolution>0.01</resolution>
          </range>
          <noise>
            <type>gaussian</type><mean>0.0</mean><stddev>0.01</stddev>
          </noise>
          <frame_id>lidar_link</frame_id>
        </lidar>
        <always_on>true</always_on>
        <visualize>false</visualize>
      </sensor>

      <!-- ============ IMU ============ -->
      <sensor name="imu_sensor" type="imu">
        <pose>0 0 0 0 0 0</pose>
        <topic>imu</topic>
        <update_rate>100</update_rate>
        <imu>
          <angular_velocity>
            <x><noise type="gaussian"><mean>0.0</mean><stddev>0.0005</stddev></noise></x>
            <y><noise type="gaussian"><mean>0.0</mean><stddev>0.0005</stddev></noise></y>
            <z><noise type="gaussian"><mean>0.0</mean><stddev>0.0005</stddev></noise></z>
          </angular_velocity>
          <linear_acceleration>
            <x><noise type="gaussian"><mean>0.0</mean><stddev>0.005</stddev></noise></x>
            <y><noise type="gaussian"><mean>0.0</mean><stddev>0.005</stddev></noise></y>
            <z><noise type="gaussian"><mean>0.0</mean><stddev>0.005</stddev></noise></z>
          </linear_acceleration>
        </imu>
        <always_on>true</always_on>
      </sensor>
    </link>

    <!-- ===================== Left wheel ===================== -->
    <link name="left_wheel_link">
      <pose>0 0.18 0.08 -1.5707 0 0</pose>
      <inertial>
        <mass>0.5</mass>
        <inertia><ixx>0.0008</ixx><iyy>0.0008</iyy><izz>0.0015</izz><ixy>0</ixy><ixz>0</ixz><iyz>0</iyz></inertia>
      </inertial>
      <collision name="col">
        <geometry><cylinder><radius>0.08</radius><length>0.04</length></cylinder></geometry>
        <surface><friction><ode><mu>1.0</mu><mu2>1.0</mu2></ode></friction></surface>
      </collision>
      <visual name="vis">
        <geometry><cylinder><radius>0.08</radius><length>0.04</length></cylinder></geometry>
        <material><ambient>0.1 0.1 0.1 1</ambient><diffuse>0.15 0.15 0.15 1</diffuse></material>
      </visual>
    </link>

    <!-- ===================== Right wheel ===================== -->
    <link name="right_wheel_link">
      <pose>0 -0.18 0.08 -1.5707 0 0</pose>
      <inertial>
        <mass>0.5</mass>
        <inertia><ixx>0.0008</ixx><iyy>0.0008</iyy><izz>0.0015</izz><ixy>0</ixy><ixz>0</ixz><iyz>0</iyz></inertia>
      </inertial>
      <collision name="col">
        <geometry><cylinder><radius>0.08</radius><length>0.04</length></cylinder></geometry>
        <surface><friction><ode><mu>1.0</mu><mu2>1.0</mu2></ode></friction></surface>
      </collision>
      <visual name="vis">
        <geometry><cylinder><radius>0.08</radius><length>0.04</length></cylinder></geometry>
        <material><ambient>0.1 0.1 0.1 1</ambient><diffuse>0.15 0.15 0.15 1</diffuse></material>
      </visual>
    </link>

    <!-- ===================== Caster (passive front wheel) ===================== -->
    <link name="caster_link">
      <pose>0.16 0 0.04 0 0 0</pose>
      <inertial>
        <mass>0.1</mass>
        <inertia><ixx>0.00004</ixx><iyy>0.00004</iyy><izz>0.00004</izz><ixy>0</ixy><ixz>0</ixz><iyz>0</iyz></inertia>
      </inertial>
      <collision name="col">
        <geometry><sphere><radius>0.04</radius></sphere></geometry>
        <surface><friction><ode><mu>0.05</mu><mu2>0.05</mu2></ode></friction></surface>
      </collision>
      <visual name="vis">
        <geometry><sphere><radius>0.04</radius></sphere></geometry>
        <material><ambient>0.1 0.1 0.1 1</ambient><diffuse>0.15 0.15 0.15 1</diffuse></material>
      </visual>
    </link>

    <!-- ===================== Joints ===================== -->
    <joint name="left_wheel_joint" type="revolute">
      <parent>base_link</parent>
      <child>left_wheel_link</child>
      <axis>
        <xyz>0 0 1</xyz>
        <limit><lower>-1e16</lower><upper>1e16</upper></limit>
      </axis>
    </joint>

    <joint name="right_wheel_joint" type="revolute">
      <parent>base_link</parent>
      <child>right_wheel_link</child>
      <axis>
        <xyz>0 0 1</xyz>
        <limit><lower>-1e16</lower><upper>1e16</upper></limit>
      </axis>
    </joint>

    <joint name="caster_joint" type="ball">
      <parent>base_link</parent>
      <child>caster_link</child>
    </joint>

    <!-- ===================== Plugins ===================== -->
    <!--
      Differential drive: subscribes to /model/agenticros_amr/cmd_vel and drives
      the wheels. Publishes /model/agenticros_amr/odometry and tf as gz topics
      that the bridge re-emits as ROS topics.
    -->
    <plugin filename="gz-sim-diff-drive-system" name="gz::sim::systems::DiffDrive">
      <left_joint>left_wheel_joint</left_joint>
      <right_joint>right_wheel_joint</right_joint>
      <wheel_separation>0.36</wheel_separation>
      <wheel_radius>0.08</wheel_radius>
      <odom_publish_frequency>50</odom_publish_frequency>
      <!--
        Intentionally NOT setting <topic> so gz-sim uses its documented default
        of /model/<model_name>/cmd_vel. The bridge in config/amr_bridge.yaml
        publishes there, so plugin and bridge agree.
        Previously had <topic>cmd_vel</topic> which gz interpreted as a
        relative/no-namespace topic and bound to /cmd_vel - the bridge then
        published into a void and the robot never moved.
      -->
      <odom_topic>odometry</odom_topic>
      <tf_topic>tf</tf_topic>
      <frame_id>odom</frame_id>
      <child_frame_id>base_link</child_frame_id>
      <max_linear_acceleration>1.0</max_linear_acceleration>
      <max_angular_acceleration>2.0</max_angular_acceleration>
    </plugin>

    <plugin filename="gz-sim-joint-state-publisher-system" name="gz::sim::systems::JointStatePublisher">
      <topic>joint_states</topic>
    </plugin>

    <!--
      Pose publisher: every link's pose relative to the world. Useful for RViz
      visualization without running robot_state_publisher with a URDF — but
      note ROS tools generally expect /tf, which the diff-drive plugin
      provides for the base + odom relationship.
    -->
    <plugin filename="gz-sim-pose-publisher-system" name="gz::sim::systems::PosePublisher">
      <publish_link_pose>true</publish_link_pose>
      <publish_sensor_pose>true</publish_sensor_pose>
      <publish_collision_pose>false</publish_collision_pose>
      <publish_visual_pose>false</publish_visual_pose>
      <publish_nested_model_pose>false</publish_nested_model_pose>
      <use_pose_vector_msg>true</use_pose_vector_msg>
      <static_publisher>true</static_publisher>
      <static_update_frequency>1</static_update_frequency>
    </plugin>

  </model>
</sdf>
